Workbook

Sheet 🏠 Dashboard
A1: Lime Premium Studios | D1: Investment Portfolio Tracker — Pro | J1: 🏠 Dashboard
A2: ="TOTAL VALUE"&CHAR(10)&(TEXT(SUM('📊 Holdings Master'!J9:J68),"$#,##0")) | C2: ="MoM CHANGE"&CHAR(10)&(TEXT(IFERROR(SUM('📊 Holdings Master'!J9:J68)-SUM('📊 Holdings Master'!H9:H68),0),"+$#,##0;-$#,##0")) | E2: ="YTD RETURN"&CHAR(10)&(TEXT(IFERROR((SUM('📊 Holdings Master'!J9:J68)/MAX(1,SUM('📊 Holdings Master'!H9:H68)))-1,0),"+0.0%;-0.0%")) | G2: ="YTD DIVIDENDS"&CHAR(10)&(TEXT(SUM('💰 Dividend Income Calendar'!N9:N28),"$#,##0")) | I2: ="POSITIONS"&CHAR(10)&(COUNTA('📊 Holdings Master'!B9:B68)) | K2: ="DRIFT STATUS"&CHAR(10)&(IFERROR(IF(MAX('📈 Asset Allocation'!F11:F20)>0.05,"🔴 Significant",IF(MAX('📈 Asset Allocation'!F11:F20)>0.02,"⚠ Mild","✓ On target")),"✓ On target"))
A3: ✦ Why a Spreadsheet, Not an App? Sharesight $96/yr. Stock Rover $300/yr. Kubera $200/yr. We charge $17 once. No broker linking — your credentials stay at your broker.
A4: Your portfolio at a glance — every KPI recomputes the moment GOOGLEFINANCE refreshes Holdings Master.
B6: Top-5 holdings by value
B7: Ranked descending. Concentration alert badge when single position exceeds 20% of portfolio.
B10: Rank | C10: Ticker | D10: Position $ | E10: % of Portfolio | F10: Concentration Flag
B11: #1 | C11: =IFERROR(INDEX('📊 Holdings Master'!B9:B68,MATCH(LARGE('📊 Holdings Master'!J9:J68,1),'📊 Holdings Master'!J9:J68,0)),"—") | D11: =IFERROR(LARGE('📊 Holdings Master'!J9:J68,1),0) | E11: =IFERROR(D11/SUM('📊 Holdings Master'!J9:J68),0) | F11: =IF(E11>0.2,"🔴 CONCENTRATION >20%",IF(E11>0.1,"⚠ Watch","✓ OK"))
B12: #2 | C12: =IFERROR(INDEX('📊 Holdings Master'!B9:B68,MATCH(LARGE('📊 Holdings Master'!J9:J68,2),'📊 Holdings Master'!J9:J68,0)),"—") | D12: =IFERROR(LARGE('📊 Holdings Master'!J9:J68,2),0) | E12: =IFERROR(D12/SUM('📊 Holdings Master'!J9:J68),0) | F12: =IF(E12>0.2,"🔴 CONCENTRATION >20%",IF(E12>0.1,"⚠ Watch","✓ OK"))
B13: #3 | C13: =IFERROR(INDEX('📊 Holdings Master'!B9:B68,MATCH(LARGE('📊 Holdings Master'!J9:J68,3),'📊 Holdings Master'!J9:J68,0)),"—") | D13: =IFERROR(LARGE('📊 Holdings Master'!J9:J68,3),0) | E13: =IFERROR(D13/SUM('📊 Holdings Master'!J9:J68),0) | F13: =IF(E13>0.2,"🔴 CONCENTRATION >20%",IF(E13>0.1,"⚠ Watch","✓ OK"))
B14: #4 | C14: =IFERROR(INDEX('📊 Holdings Master'!B9:B68,MATCH(LARGE('📊 Holdings Master'!J9:J68,4),'📊 Holdings Master'!J9:J68,0)),"—") | D14: =IFERROR(LARGE('📊 Holdings Master'!J9:J68,4),0) | E14: =IFERROR(D14/SUM('📊 Holdings Master'!J9:J68),0) | F14: =IF(E14>0.2,"🔴 CONCENTRATION >20%",IF(E14>0.1,"⚠ Watch","✓ OK"))
B15: #5 | C15: =IFERROR(INDEX('📊 Holdings Master'!B9:B68,MATCH(LARGE('📊 Holdings Master'!J9:J68,5),'📊 Holdings Master'!J9:J68,0)),"—") | D15: =IFERROR(LARGE('📊 Holdings Master'!J9:J68,5),0) | E15: =IFERROR(D15/SUM('📊 Holdings Master'!J9:J68),0) | F15: =IF(E15>0.2,"🔴 CONCENTRATION >20%",IF(E15>0.1,"⚠ Watch","✓ OK"))
B18: Asset allocation — current vs target
B19: 10 classes. Drift indicators on slices >5pp from target.
B22: Asset Class | C22: Current $ | D22: Current % | E22: Target % | F22: Drift (pp) | G22: Status
B23: Stocks | C23: =IFERROR(SUMIF('📊 Holdings Master'!D9:D68,B23,'📊 Holdings Master'!J9:J68),0) | D23: =IFERROR(C23/SUM(C23:C32),0) | E23: 0.4 | F23: =D23-E23 | G23: =IF(ABS(F23)>0.05,"🔴 Significant",IF(ABS(F23)>0.02,"⚠ Mild","✓ On target"))
B24: ETFs | C24: =IFERROR(SUMIF('📊 Holdings Master'!D9:D68,B24,'📊 Holdings Master'!J9:J68),0) | D24: =IFERROR(C24/SUM(C23:C32),0) | E24: 0.15 | F24: =D24-E24 | G24: =IF(ABS(F24)>0.05,"🔴 Significant",IF(ABS(F24)>0.02,"⚠ Mild","✓ On target"))
B25: Mutual Funds | C25: =IFERROR(SUMIF('📊 Holdings Master'!D9:D68,B25,'📊 Holdings Master'!J9:J68),0) | D25: =IFERROR(C25/SUM(C23:C32),0) | E25: 0.05 | F25: =D25-E25 | G25: =IF(ABS(F25)>0.05,"🔴 Significant",IF(ABS(F25)>0.02,"⚠ Mild","✓ On target"))
B26: Bonds | C26: =IFERROR(SUMIF('📊 Holdings Master'!D9:D68,B26,'📊 Holdings Master'!J9:J68),0) | D26: =IFERROR(C26/SUM(C23:C32),0) | E26: 0.15 | F26: =D26-E26 | G26: =IF(ABS(F26)>0.05,"🔴 Significant",IF(ABS(F26)>0.02,"⚠ Mild","✓ On target"))
B27: Cash | C27: =IFERROR(SUMIF('📊 Holdings Master'!D9:D68,B27,'📊 Holdings Master'!J9:J68),0) | D27: =IFERROR(C27/SUM(C23:C32),0) | E27: 0.05 | F27: =D27-E27 | G27: =IF(ABS(F27)>0.05,"🔴 Significant",IF(ABS(F27)>0.02,"⚠ Mild","✓ On target"))
B28: Metals | C28: =IFERROR(SUMIF('📊 Holdings Master'!D9:D68,B28,'📊 Holdings Master'!J9:J68),0) | D28: =IFERROR(C28/SUM(C23:C32),0) | E28: 0.05 | F28: =D28-E28 | G28: =IF(ABS(F28)>0.05,"🔴 Significant",IF(ABS(F28)>0.02,"⚠ Mild","✓ On target"))
B29: Crypto | C29: =IFERROR(SUMIF('📊 Holdings Master'!D9:D68,B29,'📊 Holdings Master'!J9:J68),0) | D29: =IFERROR(C29/SUM(C23:C32),0) | E29: 0.03 | F29: =D29-E29 | G29: =IF(ABS(F29)>0.05,"🔴 Significant",IF(ABS(F29)>0.02,"⚠ Mild","✓ On target"))
B30: REITs | C30: =IFERROR(SUMIF('📊 Holdings Master'!D9:D68,B30,'📊 Holdings Master'!J9:J68),0) | D30: =IFERROR(C30/SUM(C23:C32),0) | E30: 0.07 | F30: =D30-E30 | G30: =IF(ABS(F30)>0.05,"🔴 Significant",IF(ABS(F30)>0.02,"⚠ Mild","✓ On target"))
B31: CDs | C31: =IFERROR(SUMIF('📊 Holdings Master'!D9:D68,B31,'📊 Holdings Master'!J9:J68),0) | D31: =IFERROR(C31/SUM(C23:C32),0) | E31: 0.03 | F31: =D31-E31 | G31: =IF(ABS(F31)>0.05,"🔴 Significant",IF(ABS(F31)>0.02,"⚠ Mild","✓ On target"))
B32: Options/RSUs | C32: =IFERROR(SUMIF('📊 Holdings Master'!D9:D68,B32,'📊 Holdings Master'!J9:J68),0) | D32: =IFERROR(C32/SUM(C23:C32),0) | E32: 0.02 | F32: =D32-E32 | G32: =IF(ABS(F32)>0.05,"🔴 Significant",IF(ABS(F32)>0.02,"⚠ Mild","✓ On target"))
B35: Portfolio trajectory · last 24 months
B36: Snapshot-driven from monthly entries on Annual Summary tab. Charcoal = actual NAV; warm-gold = cost basis. Gap = unrealized gains.
B39: Jan | C39: Feb | D39: Mar | E39: Apr | F39: May | G39: Jun | H39: Jul | I39: Aug | J39: Sep | K39: Oct | L39: Nov
B40: =IFERROR(INDEX('💰 Dividend Income Calendar'!B9:M9,,COLUMN()-1),0) | C40: =IFERROR(INDEX('💰 Dividend Income Calendar'!B10:M10,,COLUMN()-1),0) | D40: =IFERROR(INDEX('💰 Dividend Income Calendar'!B11:M11,,COLUMN()-1),0) | E40: =IFERROR(INDEX('💰 Dividend Income Calendar'!B12:M12,,COLUMN()-1),0) | F40: =IFERROR(INDEX('💰 Dividend Income Calendar'!B13:M13,,COLUMN()-1),0) | G40: =IFERROR(INDEX('💰 Dividend Income Calendar'!B14:M14,,COLUMN()-1),0) | H40: =IFERROR(INDEX('💰 Dividend Income Calendar'!B15:M15,,COLUMN()-1),0) | I40: =IFERROR(INDEX('💰 Dividend Income Calendar'!B16:M16,,COLUMN()-1),0) | J40: =IFERROR(INDEX('💰 Dividend Income Calendar'!B17:M17,,COLUMN()-1),0) | K40: =IFERROR(INDEX('💰 Dividend Income Calendar'!B18:M18,,COLUMN()-1),0) | L40: =IFERROR(INDEX('💰 Dividend Income Calendar'!B19:M19,,COLUMN()-1),0)
B43: 📊 Dashboard inputs — verify cells light up after Holdings Master edits Asset allocation pulls SUMIF from Holdings Master column D (asset class). Top-5 uses LARGE() on column J (current value). Drift bands: ±2pp = mild, ±5pp = significant. GOOGLEFINANCE refreshes daily — close + reopen the sheet to force a refresh if KPIs look stale.
A49: Lime Premium Studios · Investment Portfolio Tracker Pro v1.0 · Privacy-first. No Plaid. No app.

Sheet 📊 Holdings Master
A1: Lime Premium Studios | D1: Investment Portfolio Tracker — Pro | J1: 📊 Holdings Master
A2: ="POSITIONS"&CHAR(10)&(COUNTA(B9:B68)) | C2: ="TOTAL VALUE"&CHAR(10)&(TEXT(SUM(J9:J68),"$#,##0")) | E2: ="COST BASIS"&CHAR(10)&(TEXT(SUM(H9:H68),"$#,##0")) | G2: ="UNREALIZED"&CHAR(10)&(TEXT(SUM(K9:K68),"+$#,##0;-$#,##0")) | I2: ="WINNERS"&CHAR(10)&(COUNTIF(K9:K68,">0")) | K2: ="LOSERS"&CHAR(10)&(COUNTIF(K9:K68,"<0"))
A3: ✦ Why a Spreadsheet, Not an App? Sharesight $96/yr. Stock Rover $300/yr. Kubera $200/yr. We charge $17 once. No broker linking — your credentials stay at your broker.
A4: Every position across 10 asset classes + 8 account types. Live Price = GOOGLEFINANCE — locked formula cell, not buyer-edited. Essentials cap: 30 positions; Pro/AI: 60.
B6: Position grid — 60 rows · 10 asset classes · 8 account types
B7: Required: Ticker (B) + Account (C) + Asset Class (D) + Shares (E) + Avg Cost (F). Live Price (I) populates via =GOOGLEFINANCE(B<row>) in Google Sheets — see callout below.
B8: G/L %
B9: VTI | C9: Brokerage Taxable | D9: ETFs | E9: 350 | F9: 185.4 | G9: 45092 | H9: =IFERROR(E9*F9,"") | I9: 245 | J9: =IFERROR(E9*I9,"") | K9: =IFERROR(J9-H9,"") | L9: =IFERROR(K9/H9,"")
B10: VOO | C10: Brokerage Taxable | D10: ETFs | E10: 60 | F10: 380.2 | G10: 45191 | H10: =IFERROR(E10*F10,"") | I10: 440 | J10: =IFERROR(E10*I10,"") | K10: =IFERROR(J10-H10,"") | L10: =IFERROR(K10/H10,"")
B11: AAPL | C11: Brokerage Taxable | D11: Stocks | E11: 80 | F11: 128 | G11: 44870 | H11: =IFERROR(E11*F11,"") | I11: 182 | J11: =IFERROR(E11*I11,"") | K11: =IFERROR(J11-H11,"") | L11: =IFERROR(K11/H11,"")
B12: MSFT | C12: Brokerage Taxable | D12: Stocks | E12: 30 | F12: 282.4 | G12: 44975 | H12: =IFERROR(E12*F12,"") | I12: 415 | J12: =IFERROR(E12*I12,"") | K12: =IFERROR(J12-H12,"") | L12: =IFERROR(K12/H12,"")
B13: GOOGL | C13: Brokerage Taxable | D13: Stocks | E13: 70 | F13: 105.5 | G13: 44995 | H13: =IFERROR(E13*F13,"") | I13: 148 | J13: =IFERROR(E13*I13,"") | K13: =IFERROR(J13-H13,"") | L13: =IFERROR(K13/H13,"")
B14: VXUS | C14: Brokerage Taxable | D14: ETFs | E14: 180 | F14: 56.8 | G14: 45099 | H14: =IFERROR(E14*F14,"") | I14: 59.8 | J14: =IFERROR(E14*I14,"") | K14: =IFERROR(J14-H14,"") | L14: =IFERROR(K14/H14,"")
B15: VNQ | C15: Brokerage Taxable | D15: REITs | E15: 165 | F15: 88.1 | G15: 45030 | H15: =IFERROR(E15*F15,"") | I15: 90.9 | J15: =IFERROR(E15*I15,"") | K15: =IFERROR(J15-H15,"") | L15: =IFERROR(K15/H15,"")
B16: BND | C16: 401k | D16: Bonds | E16: 285 | F16: 78.2 | G16: 44936 | H16: =IFERROR(E16*F16,"") | I16: 75.1 | J16: =IFERROR(E16*I16,"") | K16: =IFERROR(J16-H16,"") | L16: =IFERROR(K16/H16,"")
B17: VTSAX | C17: 401k | D17: Mutual Funds | E17: 142 | F17: 98.4 | G17: 44778 | H17: =IFERROR(E17*F17,"") | I17: 124.5 | J17: =IFERROR(E17*I17,"") | K17: =IFERROR(J17-H17,"") | L17: =IFERROR(K17/H17,"")
B18: VTSAX | C18: Roth IRA | D18: Mutual Funds | E18: 124 | F18: 88.2 | G18: 44915 | H18: =IFERROR(E18*F18,"") | I18: 124.5 | J18: =IFERROR(E18*I18,"") | K18: =IFERROR(J18-H18,"") | L18: =IFERROR(K18/H18,"")
B19: SCHD | C19: Roth IRA | D19: ETFs | E19: 220 | F19: 71.4 | G19: 45054 | H19: =IFERROR(E19*F19,"") | I19: 82.1 | J19: =IFERROR(E19*I19,"") | K19: =IFERROR(J19-H19,"") | L19: =IFERROR(K19/H19,"")
B20: VYM | C20: Roth IRA | D20: ETFs | E20: 80 | F20: 105.2 | G20: 45153 | H20: =IFERROR(E20*F20,"") | I20: 117.6 | J20: =IFERROR(E20*I20,"") | K20: =IFERROR(J20-H20,"") | L20: =IFERROR(K20/H20,"")
... B26: CASH | C26: Brokerage Taxable | D26: Cash | E26: 1 | F26: 15000 | G26: 45292 | H26: =IFERROR(E26*F26,"") | I26: 15000 | J26: =IFERROR(E26*I26,"") | K26: =IFERROR(J26-H26,"") | L26: =IFERROR(K26/H26,"")
H27: =IFERROR(E27*F27,"") | J27: =IFERROR(E27*I27,"") | K27: =IFERROR(J27-H27,"") | L27: =IFERROR(K27/H27,"")
H28: =IFERROR(E28*F28,"") | J28: =IFERROR(E28*I28,"") | K28: =IFERROR(J28-H28,"") | L28: =IFERROR(K28/H28,"")
H29: =IFERROR(E29*F29,"") | J29: =IFERROR(E29*I29,"") | K29: =IFERROR(J29-H29,"") | L29: =IFERROR(K29/H29,"")
H30: =IFERROR(E30*F30,"") | J30: =IFERROR(E30*I30,"") | K30: =IFERROR(J30-H30,"") | L30: =IFERROR(K30/H30,"")
H31: =IFERROR(E31*F31,"") | J31: =IFERROR(E31*I31,"") | K31: =IFERROR(J31-H31,"") | L31: =IFERROR(K31/H31,"")
H32: =IFERROR(E32*F32,"") | J32: =IFERROR(E32*I32,"") | K32: =IFERROR(J32-H32,"") | L32: =IFERROR(K32/H32,"")
H33: =IFERROR(E33*F33,"") | J33: =IFERROR(E33*I33,"") | K33: =IFERROR(J33-H33,"") | L33: =IFERROR(K33/H33,"")
H34: =IFERROR(E34*F34,"") | J34: =IFERROR(E34*I34,"") | K34: =IFERROR(J34-H34,"") | L34: =IFERROR(K34/H34,"")
H35: =IFERROR(E35*F35,"") | J35: =IFERROR(E35*I35,"") | K35: =IFERROR(J35-H35,"") | L35: =IFERROR(K35/H35,"")
H36: =IFERROR(E36*F36,"") | J36: =IFERROR(E36*I36,"") | K36: =IFERROR(J36-H36,"") | L36: =IFERROR(K36/H36,"")
H37: =IFERROR(E37*F37,"") | J37: =IFERROR(E37*I37,"") | K37: =IFERROR(J37-H37,"") | L37: =IFERROR(K37/H37,"")
H38: =IFERROR(E38*F38,"") | J38: =IFERROR(E38*I38,"") | K38: =IFERROR(J38-H38,"") | L38: =IFERROR(K38/H38,"")
... H68: =IFERROR(E68*F68,"") | J68: =IFERROR(E68*I68,"") | K68: =IFERROR(J68-H68,"") | L68: =IFERROR(K68/H68,"")
B70: TOTAL | H70: =SUM(H9:H68) | J70: =SUM(J9:J68) | K70: =SUM(K9:K68) | L70: =IFERROR(K70/H70,0)
B71: NFT/Illiquid Assets: Enter last-known valuation as current price. Update the date in column G when you re-value. NFT values are subjective — mark with a note in column M to flag illiquid/manually-valued positions.
B73: 📡 Live prices via GOOGLEFINANCE — Google Sheets only In Google Sheets, replace column I with `=GOOGLEFINANCE(B<row>)` per position — refreshes every ~minute when the sheet is open (20-min delayed feed). For metals/crypto, use `=GOOGLEFINANCE("CURRENCY:XAUUSD")` for gold spot and `=GOOGLEFINANCE("CURRENCY:BTCUSD")` for BTC. Excel CANNOT pull live prices — this is by-design + disclosed in listing. Excel users: keep seed values, refresh manually monthly.
A78: Lime Premium Studios · Investment Portfolio Tracker Pro v1.0 · Privacy-first. No Plaid. No app.

Sheet 💵 Cash & FX Holdings
A1: Lime Premium Studios | D1: Investment Portfolio Tracker — Pro | J1: 💵 Cash & FX Holdings
A2: ="CURRENCIES"&CHAR(10)&(COUNTA(B9:B18)) | C2: ="USD EQUIV"&CHAR(10)&(TEXT(SUM(G9:G18),"$#,##0")) | E2: BASE USD | G2: ="EUR→USD"&CHAR(10)&(IFERROR(TEXT(VLOOKUP("EUR",B9:E18,4,FALSE),"0.0000"),"—")) | I2: ="GBP→USD"&CHAR(10)&(IFERROR(TEXT(VLOOKUP("GBP",B9:E18,4,FALSE),"0.0000"),"—")) | K2: ="AS OF"&CHAR(10)&(IFERROR(TEXT(MAX(F9:F18),"mmm d"),"—"))
A3: ✦ Why a Spreadsheet, Not an App? Sharesight $96/yr. Stock Rover $300/yr. Kubera $200/yr. We charge $17 once. No broker linking — your credentials stay at your broker.
A4: Multi-currency cash positions. Live FX via GOOGLEFINANCE in Sheets. USD-equivalent column drives Holdings Master cash class.
B6: Multi-currency cash + FX
B7: Rate-to-USD shows how many USD one unit of this currency is worth. Update FX monthly or use =GOOGLEFINANCE("CURRENCY:EURUSD") in Sheets.
B10: Currency | C10: Account | D10: Balance | E10: Rate→USD | F10: Last Updated | G10: USD Equiv | H10: Notes
B11: USD | C11: Brokerage Taxable | D11: 15000 | E11: 1 | F11: 46165.537 | G11: =IFERROR(D11*E11,"") | H11: Base currency
B12: EUR | C12: Other | D12: 0 | E12: 1.07 | F12: 46165.537 | G12: =IFERROR(D12*E12,"") | H12: European Union
B13: GBP | C13: Other | D13: 0 | E13: 1.26 | F13: 46165.537 | G13: =IFERROR(D13*E13,"") | H13: United Kingdom
G14: =IFERROR(D14*E14,"")
G15: =IFERROR(D15*E15,"")
G16: =IFERROR(D16*E16,"")
G17: =IFERROR(D17*E17,"")
G18: =IFERROR(D18*E18,"")
G19: =IFERROR(D19*E19,"")
G20: =IFERROR(D20*E20,"")
B23: 🌍 FX via GOOGLEFINANCE In Google Sheets, replace column E with `=GOOGLEFINANCE("CURRENCY:EURUSD")` per row. Excel users update monthly — oanda.com or your bank's FX page. Pegged currencies (AED 0.2723, SAR 0.2667) rarely move; floaters move daily.
A29: Lime Premium Studios · Investment Portfolio Tracker Pro v1.0 · Privacy-first. No Plaid. No app.

Sheet 📈 Stocks Tracker
A1: Lime Premium Studios | D1: Investment Portfolio Tracker — Pro | J1: 📈 Stocks Tracker
A2: ="TICKERS"&CHAR(10)&(COUNTA(B9:B30)) | C2: ="AVG MoM %"&CHAR(10)&(TEXT(IFERROR(AVERAGE(L9:L30)/AVERAGE(B9:B30)-1,0),"+0.0%;-0.0%")) | E2: ="TOTAL DIV YTD"&CHAR(10)&(TEXT(SUM('💰 Dividend Income Calendar'!N9:N28),"$#,##0")) | G2: ="TOP TICKER"&CHAR(10)&(IFERROR(INDEX(B9:B30,MATCH(MAX(L9:L30),L9:L30,0)),"—")) | I2: ="AS OF"&CHAR(10)&(TEXT(TODAY(),"mmm yyyy")) | K2: SHEET RULE Monthly snapshot
A3: ✦ Why a Spreadsheet, Not an App? Sharesight $96/yr. Stock Rover $300/yr. Kubera $200/yr. We charge $17 once. No broker linking — your credentials stay at your broker.
A4: Per-ticker monthly price log. Dividend annotations on payment months. Ex-dividend date in column M.
B6: Monthly price log — last 12 months
B7: Enter end-of-month closing prices. Dividend payment months get a marker in the Notes column. Use this tab to backtest your conviction vs actual.
B10: Ticker | C10: Jan | D10: Feb | E10: Mar | F10: Apr | G10: May | H10: Jun | I10: Jul | J10: Aug | K10: Sep | L10: Oct
B11: VTI | C11: 208.25 | D11: 212.66 | E11: 217.07 | F11: 221.48 | G11: 225.89 | H11: 230.3 | I11: 234.71 | J11: 239.12 | K11: 243.53 | L11: 247.94
B12: VOO | C12: 374 | D12: 381.92 | E12: 389.84 | F12: 397.76 | G12: 405.68 | H12: 413.6 | I12: 421.52 | J12: 429.44 | K12: 437.36 | L12: 445.28
B13: AAPL | C13: 154.7 | D13: 157.98 | E13: 161.25 | F13: 164.53 | G13: 167.8 | H13: 171.08 | I13: 174.36 | J13: 177.63 | K13: 180.91 | L13: 184.18
B14: MSFT | C14: 352.75 | D14: 360.22 | E14: 367.69 | F14: 375.16 | G14: 382.63 | H14: 390.1 | I14: 397.57 | J14: 405.04 | K14: 412.51 | L14: 419.98
B15: GOOGL | C15: 125.8 | D15: 128.46 | E15: 131.13 | F15: 133.79 | G15: 136.46 | H15: 139.12 | I15: 141.78 | J15: 144.45 | K15: 147.11 | L15: 149.78
B16: VXUS | C16: 51 | D16: 52.08 | E16: 53.16 | F16: 54.24 | G16: 55.32 | H16: 56.4 | I16: 57.48 | J16: 58.56 | K16: 59.64 | L16: 60.72
B17: SCHD | C17: 69.7 | D17: 71.18 | E17: 72.65 | F17: 74.13 | G17: 75.6 | H17: 77.08 | I17: 78.56 | J17: 80.03 | K17: 81.51 | L17: 82.98
B18: VYM | C18: 100.3 | D18: 102.42 | E18: 104.55 | F18: 106.67 | G18: 108.8 | H18: 110.92 | I18: 113.04 | J18: 115.17 | K18: 117.29 | L18: 119.42
B35: 📈 Backtest your conviction When you bought AAPL at $128, what was your thesis? Compare the 12-month price log to the assumptions you wrote down then. Position Health Check (AI Edition page 9) walks this discipline. Right-aligned tabular numerics let you scan a row at a glance.
A41: Lime Premium Studios · Investment Portfolio Tracker Pro v1.0 · Privacy-first. No Plaid. No app.

Sheet 🗂️ ETFs & Mutual Funds
A1: Lime Premium Studios | D1: Investment Portfolio Tracker — Pro | J1: 🗂️ ETFs & Mutual Funds
A2: ="FUNDS"&CHAR(10)&(COUNTA(B9:B22)) | C2: ="AVG ER"&CHAR(10)&(TEXT(IFERROR(AVERAGE(F9:F22),0),"0.00%")) | E2: ="TOTAL VALUE"&CHAR(10)&(TEXT(SUM(I9:I22),"$#,##0")) | G2: ="ER COST/YR"&CHAR(10)&(TEXT(SUMPRODUCT(F9:F22,I9:I22),"$#,##0")) | I2: ="LOW-ER FUNDS"&CHAR(10)&(COUNTIF(F9:F22,"<0.001")) | K2: ="HIGH-ER FUNDS"&CHAR(10)&(COUNTIF(F9:F22,">0.0075"))
A3: ✦ Why a Spreadsheet, Not an App? Sharesight $96/yr. Stock Rover $300/yr. Kubera $200/yr. We charge $17 once. No broker linking — your credentials stay at your broker.
A4: Expense ratio highlighted — pays for itself over time. Distribution badges on payment months. Look-through to top-10 holdings.
B6: ETF + Mutual Fund holdings
B7: Expense ratio (column F) compounds against you. Below 0.10% is excellent; above 0.75% is a yellow flag worth re-evaluating.
B10: Ticker | C10: Name | D10: Type | E10: Shares | F10: Cost/sh | G10: ER | H10: NAV | I10: Cost Basis | J10: Current $ | K10: Dist Yld | L10: Last Dist
B11: VTI | C11: Vanguard Total Stock Market ETF | D11: ETF | E11: 350 | F11: 185.4 | G11: 0.0003 | H11: 245 | I11: =IFERROR(E11*F11,"") | J11: =IFERROR(E11*H11,"") | K11: 0.014 | L11: Mar
B12: VOO | C12: Vanguard S&P 500 ETF | D12: ETF | E12: 60 | F12: 380.2 | G12: 0.0003 | H12: 440 | I12: =IFERROR(E12*F12,"") | J12: =IFERROR(E12*H12,"") | K12: 0.013 | L12: Mar
B13: VXUS | C13: Vanguard Total International ETF | D13: ETF | E13: 180 | F13: 56.8 | G13: 0.0007 | H13: 59.8 | I13: =IFERROR(E13*F13,"") | J13: =IFERROR(E13*H13,"") | K13: 0.029 | L13: Jun
B14: SCHD | C14: Schwab US Dividend Equity ETF | D14: ETF | E14: 220 | F14: 71.4 | G14: 0.0006 | H14: 82.1 | I14: =IFERROR(E14*F14,"") | J14: =IFERROR(E14*H14,"") | K14: 0.034 | L14: Mar
B15: VYM | C15: Vanguard High Dividend Yield ETF | D15: ETF | E15: 80 | F15: 105.2 | G15: 0.0006 | H15: 117.6 | I15: =IFERROR(E15*F15,"") | J15: =IFERROR(E15*H15,"") | K15: 0.029 | L15: Mar
B16: VTSAX | C16: Vanguard Total Stock Mkt Index | D16: Mutual | E16: 266 | F16: 94 | G16: 0.0004 | H16: 124.5 | I16: =IFERROR(E16*F16,"") | J16: =IFERROR(E16*H16,"") | K16: 0.014 | L16: Dec
B17: BND | C17: Vanguard Total Bond Market ETF | D17: ETF | E17: 285 | F17: 78.2 | G17: 0.0003 | H17: 75.1 | I17: =IFERROR(E17*F17,"") | J17: =IFERROR(E17*H17,"") | K17: 0.041 | L17: Monthly
I18: =IFERROR(E18*F18,"") | J18: =IFERROR(E18*H18,"")
I19: =IFERROR(E19*F19,"") | J19: =IFERROR(E19*H19,"")
I20: =IFERROR(E20*F20,"") | J20: =IFERROR(E20*H20,"")
I21: =IFERROR(E21*F21,"") | J21: =IFERROR(E21*H21,"")
I22: =IFERROR(E22*F22,"") | J22: =IFERROR(E22*H22,"")
I23: =IFERROR(E23*F23,"") | J23: =IFERROR(E23*H23,"")
I24: =IFERROR(E24*F24,"") | J24: =IFERROR(E24*H24,"")
B27: 🔍 Look-through is the hidden concentration VTI + VOO share 80-90% of their top-10 holdings. If you own both, ~40% of your portfolio is the same handful of mega-caps you bought twice. The AI Edition Look-Through Analyzer (page 6) calculates true exposure across funds.
A33: Lime Premium Studios · Investment Portfolio Tracker Pro v1.0 · Privacy-first. No Plaid. No app.

Sheet 💰 Dividend Income Calendar
A1: Lime Premium Studios | D1: Investment Portfolio Tracker — Pro | J1: 💰 Dividend Income Calendar
A2: ="PAYERS"&CHAR(10)&(COUNTA(B9:B28)) | C2: ="YTD INCOME"&CHAR(10)&(TEXT(SUM(N9:N28),"$#,##0")) | E2: ="MoM AVG"&CHAR(10)&(TEXT(IFERROR(SUM(N9:N28)/12,0),"$#,##0")) | G2: ="BIG MONTH"&CHAR(10)&(IFERROR(INDEX($C$8:$M$8,MATCH(MAX(SUMPRODUCT((C9:M28))),C9:M28,0)),"—")) | I2: ="AVG YOC"&CHAR(10)&(TEXT(IFERROR(SUM(N9:N28)/SUMIF('📊 Holdings Master'!H9:H68,">0",'📊 Holdings Master'!H9:H68),0),"0.00%")) | K2: ="PAYMENTS"&CHAR(10)&(SUMPRODUCT((C9:M28>0)*1))
A3: ✦ Why a Spreadsheet, Not an App? Sharesight $96/yr. Stock Rover $300/yr. Kubera $200/yr. We charge $17 once. No broker linking — your credentials stay at your broker.
A4: 12-month forward calendar. Cash-gap-month flag where projected income is significantly lower. Yield-on-cost in column N.
B6: Projected dividend income — next 12 months
B7: Per-payer × per-month $ projected. Cash-gap months show empty cells; the AI Dividend Optimizer prompt (page 8) suggests fills.
B10: Payer | C10: Jan | D10: Feb | E10: Mar | F10: Apr | G10: May | H10: Jun | I10: Jul | J10: Aug | K10: Sep | L10: Oct | M10: Nov | N10: YTD Total
B11: SCHD | E11: 156 | H11: 156 | K11: 156 | N11: =IFERROR(SUM(C11:M11),0)
B12: VYM | E12: 74 | H12: 74 | K12: 74 | N12: =IFERROR(SUM(C12:M12),0)
B13: VNQ | E13: 38 | H13: 38 | K13: 38 | N13: =IFERROR(SUM(C13:M13),0)
B14: AAPL | D14: 19 | G14: 19 | J14: 19 | M14: 19 | N14: =IFERROR(SUM(C14:M14),0)
B15: MSFT | E15: 23 | H15: 23 | K15: 23 | N15: =IFERROR(SUM(C15:M15),0)
B16: BND | C16: 78 | D16: 78 | E16: 78 | F16: 78 | G16: 78 | H16: 78 | I16: 78 | J16: 78 | K16: 78 | L16: 78 | M16: 78 | N16: =IFERROR(SUM(C16:M16),0)
B17: VXUS | H17: 130 | N17: =IFERROR(SUM(C17:M17),0)
B18: VTI | E18: 290 | H18: 290 | K18: 290 | N18: =IFERROR(SUM(C18:M18),0)
B19: VOO | E19: 86 | H19: 86 | K19: 86 | N19: =IFERROR(SUM(C19:M19),0)
N20: =IFERROR(SUM(C20:M20),0)
N21: =IFERROR(SUM(C21:M21),0)
N22: =IFERROR(SUM(C22:M22),0)
N23: =IFERROR(SUM(C23:M23),0)
N24: =IFERROR(SUM(C24:M24),0)
N25: =IFERROR(SUM(C25:M25),0)
N26: =IFERROR(SUM(C26:M26),0)
N27: =IFERROR(SUM(C27:M27),0)
N28: =IFERROR(SUM(C28:M28),0)
N29: =IFERROR(SUM(C29:M29),0)
N30: =IFERROR(SUM(C30:M30),0)
B32: Monthly Total | C32: =SUM(C9:C28) | D32: =SUM(D9:D28) | E32: =SUM(E9:E28) | F32: =SUM(F9:F28) | G32: =SUM(G9:G28) | H32: =SUM(H9:H28) | I32: =SUM(I9:I28) | J32: =SUM(J9:J28) | ... N32: =SUM(N9:N28)
B35: 📅 Cash-gap months are an optimization opportunity Most US dividend payers cluster in Mar/Jun/Sep/Dec (quarterly cycle). Jan/Apr/Jul/Oct can be $0 — a cash-gap month. Adding a monthly-payer like O (Realty Income) or a BDC smooths the calendar. The AI Dividend Optimizer prompt (page 8) names safe candidates.
A41: Lime Premium Studios · Investment Portfolio Tracker Pro v1.0 · Privacy-first. No Plaid. No app.

Sheet 📈 Asset Allocation
A1: Lime Premium Studios | D1: Investment Portfolio Tracker — Pro | J1: 📈 Asset Allocation
A2: CLASSES 10 | C2: ="MAX DRIFT"&CHAR(10)&(TEXT(MAX(F11:F20)-MIN(F11:F20),"0.0%")) | E2: ="OFF TARGET"&CHAR(10)&(COUNTIF(F11:F20,">0.05")+COUNTIF(F11:F20,"<-0.05")) | G2: ="REBALANCE NEEDED"&CHAR(10)&(IF(OR(COUNTIF(F11:F20,">0.05")>0,COUNTIF(F11:F20,"<-0.05")>0),"YES","NO")) | I2: ="TOTAL VALUE"&CHAR(10)&(TEXT(SUM(C11:C20),"$#,##0")) | K2: ="TARGET SUM"&CHAR(10)&(TEXT(SUM(E11:E20),"0%"))
A3: ✦ Why a Spreadsheet, Not an App? Sharesight $96/yr. Stock Rover $300/yr. Kubera $200/yr. We charge $17 once. No broker linking — your credentials stay at your broker.
A4: Current vs target across 10 asset classes. Drift indicators on slices >5pp from target. Rebalancing actions list below the grid.
B6: Current vs target allocation — 10 asset classes
B7: Target % set in column E (editable). Drift = current minus target. ±2pp = mild; ±5pp = significant. Suggested rebalance moves below.
B10: Asset Class | C10: Current $ | D10: Current % | E10: Target % | F10: Drift (pp) | G10: Action | H10: Rebalance $ | I10: Method | J10: Tax Cost
B11: Stocks | C11: =IFERROR(SUMIF('📊 Holdings Master'!D9:D68,B11,'📊 Holdings Master'!J9:J68),0) | D11: =IFERROR(C11/SUM(C11:C20),0) | E11: 0.4 | F11: =D11-E11 | G11: =IF(F11>0.05,"🔴 SELL/STOP BUYING",IF(F11<-0.05,"🔴 BUY",IF(F11>0.02,"⚠ Trim",IF(F11<-0.02,"⚠ Add","✓ Hold")))) | H11: =IFERROR(E11*SUM(C11:C20)-C11,0) | I11: =IF(B11="Bonds","Contribution-rebalance",IF(B11="Cash","Direct deposit",IF(F11>0.05,"Sell taxable + tax cost","Redirect new $"))) | J11: =IF(I11="Sell taxable + tax cost",IFERROR(H11*-0.15,0),0)
B12: ETFs | C12: =IFERROR(SUMIF('📊 Holdings Master'!D9:D68,B12,'📊 Holdings Master'!J9:J68),0) | D12: =IFERROR(C12/SUM(C11:C20),0) | E12: 0.15 | F12: =D12-E12 | G12: =IF(F12>0.05,"🔴 SELL/STOP BUYING",IF(F12<-0.05,"🔴 BUY",IF(F12>0.02,"⚠ Trim",IF(F12<-0.02,"⚠ Add","✓ Hold")))) | H12: =IFERROR(E12*SUM(C11:C20)-C12,0) | I12: =IF(B12="Bonds","Contribution-rebalance",IF(B12="Cash","Direct deposit",IF(F12>0.05,"Sell taxable + tax cost","Redirect new $"))) | J12: =IF(I12="Sell taxable + tax cost",IFERROR(H12*-0.15,0),0)
B13: Mutual Funds | C13: =IFERROR(SUMIF('📊 Holdings Master'!D9:D68,B13,'📊 Holdings Master'!J9:J68),0) | D13: =IFERROR(C13/SUM(C11:C20),0) | E13: 0.05 | F13: =D13-E13 | G13: =IF(F13>0.05,"🔴 SELL/STOP BUYING",IF(F13<-0.05,"🔴 BUY",IF(F13>0.02,"⚠ Trim",IF(F13<-0.02,"⚠ Add","✓ Hold")))) | H13: =IFERROR(E13*SUM(C11:C20)-C13,0) | I13: =IF(B13="Bonds","Contribution-rebalance",IF(B13="Cash","Direct deposit",IF(F13>0.05,"Sell taxable + tax cost","Redirect new $"))) | J13: =IF(I13="Sell taxable + tax cost",IFERROR(H13*-0.15,0),0)
B14: Bonds | C14: =IFERROR(SUMIF('📊 Holdings Master'!D9:D68,B14,'📊 Holdings Master'!J9:J68),0) | D14: =IFERROR(C14/SUM(C11:C20),0) | E14: 0.15 | F14: =D14-E14 | G14: =IF(F14>0.05,"🔴 SELL/STOP BUYING",IF(F14<-0.05,"🔴 BUY",IF(F14>0.02,"⚠ Trim",IF(F14<-0.02,"⚠ Add","✓ Hold")))) | H14: =IFERROR(E14*SUM(C11:C20)-C14,0) | I14: =IF(B14="Bonds","Contribution-rebalance",IF(B14="Cash","Direct deposit",IF(F14>0.05,"Sell taxable + tax cost","Redirect new $"))) | J14: =IF(I14="Sell taxable + tax cost",IFERROR(H14*-0.15,0),0)
B15: Cash | C15: =IFERROR(SUMIF('📊 Holdings Master'!D9:D68,B15,'📊 Holdings Master'!J9:J68),0) | D15: =IFERROR(C15/SUM(C11:C20),0) | E15: 0.05 | F15: =D15-E15 | G15: =IF(F15>0.05,"🔴 SELL/STOP BUYING",IF(F15<-0.05,"🔴 BUY",IF(F15>0.02,"⚠ Trim",IF(F15<-0.02,"⚠ Add","✓ Hold")))) | H15: =IFERROR(E15*SUM(C11:C20)-C15,0) | I15: =IF(B15="Bonds","Contribution-rebalance",IF(B15="Cash","Direct deposit",IF(F15>0.05,"Sell taxable + tax cost","Redirect new $"))) | J15: =IF(I15="Sell taxable + tax cost",IFERROR(H15*-0.15,0),0)
B16: Metals | C16: =IFERROR(SUMIF('📊 Holdings Master'!D9:D68,B16,'📊 Holdings Master'!J9:J68),0) | D16: =IFERROR(C16/SUM(C11:C20),0) | E16: 0.05 | F16: =D16-E16 | G16: =IF(F16>0.05,"🔴 SELL/STOP BUYING",IF(F16<-0.05,"🔴 BUY",IF(F16>0.02,"⚠ Trim",IF(F16<-0.02,"⚠ Add","✓ Hold")))) | H16: =IFERROR(E16*SUM(C11:C20)-C16,0) | I16: =IF(B16="Bonds","Contribution-rebalance",IF(B16="Cash","Direct deposit",IF(F16>0.05,"Sell taxable + tax cost","Redirect new $"))) | J16: =IF(I16="Sell taxable + tax cost",IFERROR(H16*-0.15,0),0)
B17: Crypto | C17: =IFERROR(SUMIF('📊 Holdings Master'!D9:D68,B17,'📊 Holdings Master'!J9:J68),0) | D17: =IFERROR(C17/SUM(C11:C20),0) | E17: 0.03 | F17: =D17-E17 | G17: =IF(F17>0.05,"🔴 SELL/STOP BUYING",IF(F17<-0.05,"🔴 BUY",IF(F17>0.02,"⚠ Trim",IF(F17<-0.02,"⚠ Add","✓ Hold")))) | H17: =IFERROR(E17*SUM(C11:C20)-C17,0) | I17: =IF(B17="Bonds","Contribution-rebalance",IF(B17="Cash","Direct deposit",IF(F17>0.05,"Sell taxable + tax cost","Redirect new $"))) | J17: =IF(I17="Sell taxable + tax cost",IFERROR(H17*-0.15,0),0)
B18: REITs | C18: =IFERROR(SUMIF('📊 Holdings Master'!D9:D68,B18,'📊 Holdings Master'!J9:J68),0) | D18: =IFERROR(C18/SUM(C11:C20),0) | E18: 0.07 | F18: =D18-E18 | G18: =IF(F18>0.05,"🔴 SELL/STOP BUYING",IF(F18<-0.05,"🔴 BUY",IF(F18>0.02,"⚠ Trim",IF(F18<-0.02,"⚠ Add","✓ Hold")))) | H18: =IFERROR(E18*SUM(C11:C20)-C18,0) | I18: =IF(B18="Bonds","Contribution-rebalance",IF(B18="Cash","Direct deposit",IF(F18>0.05,"Sell taxable + tax cost","Redirect new $"))) | J18: =IF(I18="Sell taxable + tax cost",IFERROR(H18*-0.15,0),0)
B19: CDs | C19: =IFERROR(SUMIF('📊 Holdings Master'!D9:D68,B19,'📊 Holdings Master'!J9:J68),0) | D19: =IFERROR(C19/SUM(C11:C20),0) | E19: 0.03 | F19: =D19-E19 | G19: =IF(F19>0.05,"🔴 SELL/STOP BUYING",IF(F19<-0.05,"🔴 BUY",IF(F19>0.02,"⚠ Trim",IF(F19<-0.02,"⚠ Add","✓ Hold")))) | H19: =IFERROR(E19*SUM(C11:C20)-C19,0) | I19: =IF(B19="Bonds","Contribution-rebalance",IF(B19="Cash","Direct deposit",IF(F19>0.05,"Sell taxable + tax cost","Redirect new $"))) | J19: =IF(I19="Sell taxable + tax cost",IFERROR(H19*-0.15,0),0)
B20: Options/RSUs | C20: =IFERROR(SUMIF('📊 Holdings Master'!D9:D68,B20,'📊 Holdings Master'!J9:J68),0) | D20: =IFERROR(C20/SUM(C11:C20),0) | E20: 0.02 | F20: =D20-E20 | G20: =IF(F20>0.05,"🔴 SELL/STOP BUYING",IF(F20<-0.05,"🔴 BUY",IF(F20>0.02,"⚠ Trim",IF(F20<-0.02,"⚠ Add","✓ Hold")))) | H20: =IFERROR(E20*SUM(C11:C20)-C20,0) | I20: =IF(B20="Bonds","Contribution-rebalance",IF(B20="Cash","Direct deposit",IF(F20>0.05,"Sell taxable + tax cost","Redirect new $"))) | J20: =IF(I20="Sell taxable + tax cost",IFERROR(H20*-0.15,0),0)
B23: ⚖️ Contribution-rebalancing > sell-rebalancing in taxable accounts Selling appreciated taxable holdings realizes capital gains. Redirecting NEW contributions to underweight classes closes drift over 6-12 months with zero tax cost. The AI Allocation Advisor (page 3) names which moves to do this quarter vs which to defer.
A29: Lime Premium Studios · Investment Portfolio Tracker Pro v1.0 · Privacy-first. No Plaid. No app.

Sheet 📊 Annual Summary
A1: Lime Premium Studios | D1: Investment Portfolio Tracker — Pro | J1: 📊 Annual Summary
A2: ="YTD RETURN"&CHAR(10)&(TEXT(IFERROR((SUM('📊 Holdings Master'!J9:J68)/MAX(1,SUM('📊 Holdings Master'!H9:H68)))-1,0),"+0.0%;-0.0%")) | C2: ="YTD DIVIDENDS"&CHAR(10)&(TEXT(SUM('💰 Dividend Income Calendar'!N9:N28),"$#,##0")) | E2: ="CONTRIBUTIONS"&CHAR(10)&(TEXT(SUM(D10:D21),"$#,##0")) | G2: ="REALIZED $"&CHAR(10)&(TEXT(SUM(F10:F21),"$#,##0")) | I2: ="BEST POS"&CHAR(10)&(IFERROR(INDEX('📊 Holdings Master'!B9:B68,MATCH(MAX('📊 Holdings Master'!L9:L68),'📊 Holdings Master'!L9:L68,0)),"—")) | K2: ="WORST POS"&CHAR(10)&(IFERROR(INDEX('📊 Holdings Master'!B9:B68,MATCH(MIN('📊 Holdings Master'!L9:L68),'📊 Holdings Master'!L9:L68,0)),"—"))
A3: ✦ Why a Spreadsheet, Not an App? Sharesight $96/yr. Stock Rover $300/yr. Kubera $200/yr. We charge $17 once. No broker linking — your credentials stay at your broker.
A4: Year-end snapshot — total return / dividends / realized gains-losses / contributions. Best + worst position callouts.
B6: Monthly contributions + realized P&L log
B7: Per-month log: contributions (new $), withdrawals, realized gain/loss from sells. Feeds the Quarterly Review AI prompt.
B10: Month | C10: Portfolio $ | D10: Contributions | E10: Withdrawals | F10: Realized G/L | G10: Dividends | H10: Fees | I10: MoM Δ | J10: YoY Δ
B11: Jan | C11: 258000 | D11: 1800 | E11: 0 | F11: 0 | G11: =IFERROR(INDEX('💰 Dividend Income Calendar'!C32:C32,1),0) | H11: 0 | I11: =0 | J11: =0
B12: Feb | C12: 262500 | D12: 1800 | E12: 0 | F12: 0 | G12: =IFERROR(INDEX('💰 Dividend Income Calendar'!C32:C32,1),0) | H12: 0 | I12: =IFERROR((C12/C11)-1,0) | J12: =IFERROR((C12/C11)-1,0)
B13: Mar | C13: 268000 | D13: 1800 | E13: 0 | F13: 0 | G13: =IFERROR(INDEX('💰 Dividend Income Calendar'!C32:C32,1),0) | H13: 0 | I13: =IFERROR((C13/C12)-1,0) | J13: =IFERROR((C13/C11)-1,0)
B14: Apr | C14: 264500 | D14: 1800 | E14: 0 | F14: 0 | G14: =IFERROR(INDEX('💰 Dividend Income Calendar'!C32:C32,1),0) | H14: 0 | I14: =IFERROR((C14/C13)-1,0) | J14: =IFERROR((C14/C11)-1,0)
B15: May | C15: 270500 | D15: 1800 | E15: 0 | F15: 0 | G15: =IFERROR(INDEX('💰 Dividend Income Calendar'!C32:C32,1),0) | H15: 0 | I15: =IFERROR((C15/C14)-1,0) | J15: =IFERROR((C15/C11)-1,0)
B16: Jun | C16: 276000 | D16: 1800 | E16: 0 | F16: 0 | G16: =IFERROR(INDEX('💰 Dividend Income Calendar'!C32:C32,1),0) | H16: 0 | I16: =IFERROR((C16/C15)-1,0) | J16: =IFERROR((C16/C11)-1,0)
B17: Jul | C17: 282500 | D17: 1800 | E17: 0 | F17: 0 | G17: =IFERROR(INDEX('💰 Dividend Income Calendar'!C32:C32,1),0) | H17: 0 | I17: =IFERROR((C17/C16)-1,0) | J17: =IFERROR((C17/C11)-1,0)
B18: Aug | C18: 286500 | D18: 1800 | E18: 0 | F18: 0 | G18: =IFERROR(INDEX('💰 Dividend Income Calendar'!C32:C32,1),0) | H18: 0 | I18: =IFERROR((C18/C17)-1,0) | J18: =IFERROR((C18/C11)-1,0)
B19: Sep | C19: 280500 | D19: 1800 | E19: 0 | F19: 0 | G19: =IFERROR(INDEX('💰 Dividend Income Calendar'!C32:C32,1),0) | H19: 0 | I19: =IFERROR((C19/C18)-1,0) | J19: =IFERROR((C19/C11)-1,0)
B20: Oct | C20: 285000 | D20: 1800 | E20: 0 | F20: 0 | G20: =IFERROR(INDEX('💰 Dividend Income Calendar'!C32:C32,1),0) | H20: 0 | I20: =IFERROR((C20/C19)-1,0) | J20: =IFERROR((C20/C11)-1,0)
B21: Nov | C21: 289000 | D21: 1800 | E21: 0 | F21: 0 | G21: =IFERROR(INDEX('💰 Dividend Income Calendar'!C32:C32,1),0) | H21: 0 | I21: =IFERROR((C21/C20)-1,0) | J21: =IFERROR((C21/C11)-1,0)
B22: Dec | C22: 290500 | D22: 1800 | E22: 0 | F22: 0 | G22: =IFERROR(INDEX('💰 Dividend Income Calendar'!C32:C32,1),0) | H22: 0 | I22: =IFERROR((C22/C21)-1,0) | J22: =IFERROR((C22/C11)-1,0)
B25: 📅 Year-end review uses this tab The AI Quarterly Portfolio Review prompt (page 10) reads this tab. Hand-fill contributions monthly; the rest auto-populates from Holdings Master + Dividend Calendar. Realized G/L is manual — log on the month you executed the trade, not when you booked the loss.
A31: Lime Premium Studios · Investment Portfolio Tracker Pro v1.0 · Privacy-first. No Plaid. No app.

Sheet 💵 Bonds & Fixed Income
A1: Lime Premium Studios | D1: Investment Portfolio Tracker — Pro | J1: 💵 Bonds & Fixed Income
A2: ="BONDS"&CHAR(10)&(COUNTA(B9:B22)) | C2: ="PRINCIPAL"&CHAR(10)&(TEXT(SUM(E9:E22),"$#,##0")) | E2: ="AVG YTM"&CHAR(10)&(TEXT(IFERROR(AVERAGE(I9:I22),0),"0.00%")) | G2: ="NEAREST MAT"&CHAR(10)&(IFERROR(TEXT(MIN(G9:G22),"mmm d, yyyy"),"—")) | I2: ="COUPONS/YR"&CHAR(10)&(TEXT(SUMPRODUCT(E9:E22,H9:H22),"$#,##0")) | K2: ="MAT NEXT 12mo"&CHAR(10)&(COUNTIFS(G9:G22,"<="&EDATE(TODAY(),12),G9:G22,">="&TODAY()))
A3: ✦ Why a Spreadsheet, Not an App? Sharesight $96/yr. Stock Rover $300/yr. Kubera $200/yr. We charge $17 once. No broker linking — your credentials stay at your broker.
A4: Government / corporate / municipal bonds + CDs + Treasury bills. Maturity calendar + coupon schedule + YTM.
B6: Bond ladder + fixed-income holdings
B7: Per-bond: issuer + type + principal + coupon + maturity + YTM. Maturity calendar visualizes when each instrument matures.
B10: Bond/CD | C10: Type | D10: Issuer | E10: Principal | F10: Coupon Rate | G10: Maturity | H10: Coupon $/yr | I10: Curr Price | J10: YTM | K10: Account | L10: Notes
B11: BND | C11: ETF | D11: Vanguard Bond Index | E11: 21404 | F11: 0.041 | G11: 47484 | H11: =IFERROR(E11*F11,"") | I11: 75.1 | J11: 0.045 | K11: 401k
B12: CD-1Y | C12: CD | D12: Marcus by Goldman | E12: 10000 | F12: 0.05 | G12: 45672 | H12: =IFERROR(E12*F12,"") | I12: 100 | J12: 0.05 | K12: Brokerage Taxable
B13: T-Bill | C13: Treasury | D13: US Treasury 13-wk | E13: 5000 | F13: 0.0525 | G13: 45717 | H13: =IFERROR(E13*F13,"") | I13: 100 | J13: 0.0525 | K13: Brokerage Taxable
H14: =IFERROR(E14*F14,"")
H15: =IFERROR(E15*F15,"")
H16: =IFERROR(E16*F16,"")
H17: =IFERROR(E17*F17,"")
H18: =IFERROR(E18*F18,"")
H19: =IFERROR(E19*F19,"")
H20: =IFERROR(E20*F20,"")
H21: =IFERROR(E21*F21,"")
H22: =IFERROR(E22*F22,"")
H23: =IFERROR(E23*F23,"")
H24: =IFERROR(E24*F24,"")
B27: 📅 Maturity calendar — when does cash come back? Bonds + CDs are predictable cash-return events. Logging maturity dates lets you plan reinvestment + match cash availability to upcoming expenses. T-bills + short CDs are a yield-plus-liquidity ladder during high-rate cycles.
A33: Lime Premium Studios · Investment Portfolio Tracker Pro v1.0 · Privacy-first. No Plaid. No app.

Sheet 🥇 Precious Metals
A1: Lime Premium Studios | D1: Investment Portfolio Tracker — Pro | J1: 🥇 Precious Metals
A2: ="METALS $"&CHAR(10)&(TEXT(SUM(H9:H14),"$#,##0")) | C2: ="GOLD oz"&CHAR(10)&(IFERROR(D9,"—")) | E2: ="SILVER oz"&CHAR(10)&(IFERROR(D10,"—")) | G2: ="COST BASIS"&CHAR(10)&(TEXT(SUM(F9:F14),"$#,##0")) | I2: ="UNREALIZED"&CHAR(10)&(TEXT(SUM(I9:I14),"+$#,##0;-$#,##0")) | K2: ="INSURED"&CHAR(10)&(COUNTIF(L9:L14,"✓"))
A3: ✦ Why a Spreadsheet, Not an App? Sharesight $96/yr. Stock Rover $300/yr. Kubera $200/yr. We charge $17 once. No broker linking — your credentials stay at your broker.
A4: Gold / Silver / Platinum / Palladium. Spot price via GOOGLEFINANCE in Sheets. Storage + insurance tracked.
B6: Precious metals holdings
B7: Spot price refreshes in Sheets via GOOGLEFINANCE. Insured? helps with theft-loss casualty deduction case (consult a CPA).
B10: Metal | C10: Form | D10: Ounces | E10: Cost/oz | F10: Cost basis | G10: Spot/oz | H10: Current $ | I10: Gain/Loss | J10: YTD % | K10: Storage | L10: Insured
B11: Gold | C11: Coins/Bars | D11: 2.5 | E11: 1820 | F11: =IFERROR(D11*E11,"") | G11: 2420 | H11: =IFERROR(D11*G11,"") | I11: =IFERROR(H11-F11,"") | J11: =IFERROR(I11/F11,"") | K11: Bank Safe Dep Box | L11: ✓
B12: Silver | C12: Coins | D12: 12 | E12: 23.4 | F12: =IFERROR(D12*E12,"") | G12: 31.8 | H12: =IFERROR(D12*G12,"") | I12: =IFERROR(H12-F12,"") | J12: =IFERROR(I12/F12,"") | K12: Home Safe
B13: Platinum | C13: Bars | D13: 0 | E13: 0 | F13: =IFERROR(D13*E13,"") | G13: 0 | H13: =IFERROR(D13*G13,"") | I13: =IFERROR(H13-F13,"") | J13: =IFERROR(I13/F13,"")
B14: Palladium | C14: Bars | D14: 0 | E14: 0 | F14: =IFERROR(D14*E14,"") | G14: 0 | H14: =IFERROR(D14*G14,"") | I14: =IFERROR(H14-F14,"") | J14: =IFERROR(I14/F14,"")
F15: =IFERROR(D15*E15,"") | H15: =IFERROR(D15*G15,"") | I15: =IFERROR(H15-F15,"") | J15: =IFERROR(I15/F15,"")
F16: =IFERROR(D16*E16,"") | H16: =IFERROR(D16*G16,"") | I16: =IFERROR(H16-F16,"") | J16: =IFERROR(I16/F16,"")
B18: 🥇 Spot via GOOGLEFINANCE Gold: `=GOOGLEFINANCE("CURRENCY:XAUUSD")`. Silver: `=GOOGLEFINANCE("CURRENCY:XAGUSD")`. Platinum: XPTUSD. Palladium: XPDUSD. Excel users update monthly from kitco.com. Insurance + storage tracked here because metals are uninsured by default and the casualty-loss tax case requires it.
A24: Lime Premium Studios · Investment Portfolio Tracker Pro v1.0 · Privacy-first. No Plaid. No app.

Sheet 💎 Crypto Tracker
A1: Lime Premium Studios | D1: Investment Portfolio Tracker — Pro | J1: 💎 Crypto Tracker
A2: ="COINS"&CHAR(10)&(COUNTA(B9:B22)) | C2: ="TOTAL $"&CHAR(10)&(TEXT(SUM(H9:H22),"$#,##0")) | E2: ="BTC"&CHAR(10)&(IFERROR(D9,"—")) | G2: ="ETH"&CHAR(10)&(IFERROR(D10,"—")) | I2: ="COLD WALLET"&CHAR(10)&(COUNTIF(L9:L22,"✓")) | K2: ="EXCHANGES"&CHAR(10)&(SUMPRODUCT(1/COUNTIF(J9:J22,J9:J22&"")))
A3: ✦ Why a Spreadsheet, Not an App? Sharesight $96/yr. Stock Rover $300/yr. Kubera $200/yr. We charge $17 once. No broker linking — your credentials stay at your broker.
A4: BTC / ETH / altcoins per exchange + wallet. Anonymized-by-default label option (no exchange names in screenshots).
B6: Crypto holdings — exchange + wallet location
B7: Anonymize column J ("Exchange 1" / "Wallet A") if you screenshot. Cold-wallet flag in column L = self-custody (hardware wallet or paper).
B10: Coin | C10: Network | D10: Quantity | E10: Cost/coin | F10: Cost basis | G10: Current $ | H10: Current value | I10: Gain/Loss | J10: % Portfolio | K10: Exchange/Wallet | L10: Cold?
B11: BTC | C11: Bitcoin | D11: 0.42 | E11: 28000 | F11: =IFERROR(D11*E11,"") | G11: 65000 | H11: =IFERROR(D11*G11,"") | I11: =IFERROR(H11-F11,"") | J11: =IFERROR(H11/SUM('📊 Holdings Master'!J9:J68),"") | K11: Exchange 1
B12: ETH | C12: Ethereum | D12: 2.1 | E12: 1850 | F12: =IFERROR(D12*E12,"") | G12: 3200 | H12: =IFERROR(D12*G12,"") | I12: =IFERROR(H12-F12,"") | J12: =IFERROR(H12/SUM('📊 Holdings Master'!J9:J68),"") | K12: Cold Wallet | L12: ✓
B13: SOL | C13: Solana | D13: 0 | E13: 0 | F13: =IFERROR(D13*E13,"") | G13: 0 | H13: =IFERROR(D13*G13,"") | I13: =IFERROR(H13-F13,"") | J13: =IFERROR(H13/SUM('📊 Holdings Master'!J9:J68),"")
F14: =IFERROR(D14*E14,"") | H14: =IFERROR(D14*G14,"") | I14: =IFERROR(H14-F14,"") | J14: =IFERROR(H14/SUM('📊 Holdings Master'!J9:J68),"")
F15: =IFERROR(D15*E15,"") | H15: =IFERROR(D15*G15,"") | I15: =IFERROR(H15-F15,"") | J15: =IFERROR(H15/SUM('📊 Holdings Master'!J9:J68),"")
F16: =IFERROR(D16*E16,"") | H16: =IFERROR(D16*G16,"") | I16: =IFERROR(H16-F16,"") | J16: =IFERROR(H16/SUM('📊 Holdings Master'!J9:J68),"")
F17: =IFERROR(D17*E17,"") | H17: =IFERROR(D17*G17,"") | I17: =IFERROR(H17-F17,"") | J17: =IFERROR(H17/SUM('📊 Holdings Master'!J9:J68),"")
F18: =IFERROR(D18*E18,"") | H18: =IFERROR(D18*G18,"") | I18: =IFERROR(H18-F18,"") | J18: =IFERROR(H18/SUM('📊 Holdings Master'!J9:J68),"")
F19: =IFERROR(D19*E19,"") | H19: =IFERROR(D19*G19,"") | I19: =IFERROR(H19-F19,"") | J19: =IFERROR(H19/SUM('📊 Holdings Master'!J9:J68),"")
F20: =IFERROR(D20*E20,"") | H20: =IFERROR(D20*G20,"") | I20: =IFERROR(H20-F20,"") | J20: =IFERROR(H20/SUM('📊 Holdings Master'!J9:J68),"")
F21: =IFERROR(D21*E21,"") | H21: =IFERROR(D21*G21,"") | I21: =IFERROR(H21-F21,"") | J21: =IFERROR(H21/SUM('📊 Holdings Master'!J9:J68),"")
F22: =IFERROR(D22*E22,"") | H22: =IFERROR(D22*G22,"") | I22: =IFERROR(H22-F22,"") | J22: =IFERROR(H22/SUM('📊 Holdings Master'!J9:J68),"")
B23: Stablecoins (USDC, USDT, DAI) = enter price $1.00, asset class 'Cash'. Volatile crypto (BTC, ETH, SOL) carries significant risk. Staking rewards = taxable income in most jurisdictions — consult a tax advisor. | F23: =IFERROR(D23*E23,"") | H23: =IFERROR(D23*G23,"") | I23: =IFERROR(H23-F23,"") | J23: =IFERROR(H23/SUM('📊 Holdings Master'!J9:J68),"")
F24: =IFERROR(D24*E24,"") | H24: =IFERROR(D24*G24,"") | I24: =IFERROR(H24-F24,"") | J24: =IFERROR(H24/SUM('📊 Holdings Master'!J9:J68),"")
B26: 🔐 Cold wallet = self-custody. Hot wallet = exchange-held Crypto held on exchanges (Coinbase, Binance, Kraken) = "hot" — you don't actually own the private keys, the exchange does. Cold wallet (Ledger / Trezor / paper) = you hold the keys. After FTX 2022, the rule "not your keys, not your coins" became conventional wisdom. Cold-flag column tracks which is which.
A32: Lime Premium Studios · Investment Portfolio Tracker Pro v1.0 · Privacy-first. No Plaid. No app.

Sheet 🏢 REITs Tracker
A1: Lime Premium Studios | D1: Investment Portfolio Tracker — Pro | J1: 🏢 REITs Tracker
A2: ="REITS"&CHAR(10)&(COUNTA(B9:B20)) | C2: ="POSITION $"&CHAR(10)&(TEXT(SUM(H9:H20),"$#,##0")) | E2: ="AVG YIELD"&CHAR(10)&(TEXT(IFERROR(SUMPRODUCT(H9:H20,I9:I20)/SUM(H9:H20),0),"0.00%")) | G2: ="DIV $/YR"&CHAR(10)&(TEXT(SUMPRODUCT(H9:H20,I9:I20),"$#,##0")) | I2: ="IN ROTH"&CHAR(10)&(COUNTIF(K9:K20,"Roth IRA")) | K2: ="AVG FFO"&CHAR(10)&(TEXT(IFERROR(AVERAGE(J9:J20),0),"$#,##0.00"))
A3: ✦ Why a Spreadsheet, Not an App? Sharesight $96/yr. Stock Rover $300/yr. Kubera $200/yr. We charge $17 once. No broker linking — your credentials stay at your broker.
A4: REIT-specific: FFO (vs EPS), sector breakdown, dividend yield. Non-qualified dividends best held in Roth IRA.
B6: REIT holdings + sector breakdown
B7: FFO (Funds From Operations) is the REIT P/E equivalent. Sectors: Industrial, Residential, Healthcare, Office, Data Center, Retail, Specialty.
B10: Ticker | C10: Name | D10: Sector | E10: Shares | F10: Cost/sh | G10: Price | H10: Position $ | I10: Yield | J10: FFO/sh | K10: Account | L10: Notes
B11: VNQ | C11: Vanguard Real Estate ETF | D11: Diversified | E11: 165 | F11: 88.1 | G11: 90.9 | H11: =IFERROR(E11*G11,"") | I11: 0.038 | J11: 0 | K11: Brokerage Taxable
B12: O | C12: Realty Income Corp | D12: Retail (Net Lease) | E12: 0 | F12: 0 | G12: 0 | H12: =IFERROR(E12*G12,"") | I12: 0 | J12: 4.05
B13: PLD | C13: Prologis Inc | D13: Industrial | E13: 0 | F13: 0 | G13: 0 | H13: =IFERROR(E13*G13,"") | I13: 0 | J13: 5.7
H14: =IFERROR(E14*G14,"")
H15: =IFERROR(E15*G15,"")
H16: =IFERROR(E16*G16,"")
H17: =IFERROR(E17*G17,"")
H18: =IFERROR(E18*G18,"")
H19: =IFERROR(E19*G19,"")
H20: =IFERROR(E20*G20,"")
H21: =IFERROR(E21*G21,"")
H22: =IFERROR(E22*G22,"")
B25: 🏢 REIT placement matters more than yield-chase REIT dividends are NON-qualified — taxed as ordinary income at your marginal rate (24-37% federal + state). Same yield in a Roth IRA = tax-free forever. The AI Dividend Income Optimizer (page 8) flags this misplacement specifically.
A31: Lime Premium Studios · Investment Portfolio Tracker Pro v1.0 · Privacy-first. No Plaid. No app.

Sheet 🎁 Options & RSUs
A1: Lime Premium Studios | D1: Investment Portfolio Tracker — Pro | J1: 🎁 Options & RSUs
A2: ="GRANTS"&CHAR(10)&(COUNTA(B9:B22)+COUNTA(B27:B40)) | C2: ="VESTED $"&CHAR(10)&(TEXT(SUM(I27:I40),"$#,##0")) | E2: ="UNVESTED $"&CHAR(10)&(TEXT(SUM(J27:J40),"$#,##0")) | G2: ="OPTIONS DELTA"&CHAR(10)&(TEXT(IFERROR(SUMPRODUCT(E9:E22,F9:F22),0),"$#,##0")) | I2: ="EXPIRING <90d"&CHAR(10)&(COUNTIFS(H9:H22,"<="&(TODAY()+90),H9:H22,">="&TODAY())) | K2: ="EMP CONC %"&CHAR(10)&(TEXT(IFERROR((SUM(I27:I40))/SUM('📊 Holdings Master'!J9:J68),0),"0.0%"))
A3: ✦ Why a Spreadsheet, Not an App? Sharesight $96/yr. Stock Rover $300/yr. Kubera $200/yr. We charge $17 once. No broker linking — your credentials stay at your broker.
A4: Equity comp tracker. Strike/expiry/delta for options. Vesting calendar for RSUs. Concentration alert ribbon when employer stock exceeds 10% of portfolio.
B6: =IF((SUM(I27:I40))/MAX(1,SUM('📊 Holdings Master'!J9:J68))>0.1,"🔴 EMPLOYER STOCK >10% OF PORTFOLIO — concentration risk compounds with employment risk. Consider sell-on-vest policy.","✓ Employer stock concentration within healthy band (<10% of portfolio)")
B7: Options grants
B8: Calls + puts + warrants. Delta = $ change per $1 underlying move. Expiry watch in column H.
B11: Ticker | C11: Type | D11: Strike | E11: Contracts | F11: Delta | G11: Cost basis | H11: Current $ | I11: Expiry | J11: Days Left | K11: Gain/Loss | L11: Status
I12: =IFERROR(H12-TODAY(),"") | J12: =IFERROR(G12-F12,"") | K12: =IF(I12="","",IF(I12<30,"⚠ Expiring",IF(I12<90,"Watch","OK")))
I13: =IFERROR(H13-TODAY(),"") | J13: =IFERROR(G13-F13,"") | K13: =IF(I13="","",IF(I13<30,"⚠ Expiring",IF(I13<90,"Watch","OK")))
I14: =IFERROR(H14-TODAY(),"") | J14: =IFERROR(G14-F14,"") | K14: =IF(I14="","",IF(I14<30,"⚠ Expiring",IF(I14<90,"Watch","OK")))
I15: =IFERROR(H15-TODAY(),"") | J15: =IFERROR(G15-F15,"") | K15: =IF(I15="","",IF(I15<30,"⚠ Expiring",IF(I15<90,"Watch","OK")))
I16: =IFERROR(H16-TODAY(),"") | J16: =IFERROR(G16-F16,"") | K16: =IF(I16="","",IF(I16<30,"⚠ Expiring",IF(I16<90,"Watch","OK")))
I17: =IFERROR(H17-TODAY(),"") | J17: =IFERROR(G17-F17,"") | K17: =IF(I17="","",IF(I17<30,"⚠ Expiring",IF(I17<90,"Watch","OK")))
I18: =IFERROR(H18-TODAY(),"") | J18: =IFERROR(G18-F18,"") | K18: =IF(I18="","",IF(I18<30,"⚠ Expiring",IF(I18<90,"Watch","OK")))
I19: =IFERROR(H19-TODAY(),"") | J19: =IFERROR(G19-F19,"") | K19: =IF(I19="","",IF(I19<30,"⚠ Expiring",IF(I19<90,"Watch","OK")))
I20: =IFERROR(H20-TODAY(),"") | J20: =IFERROR(G20-F20,"") | K20: =IF(I20="","",IF(I20<30,"⚠ Expiring",IF(I20<90,"Watch","OK")))
I21: =IFERROR(H21-TODAY(),"") | J21: =IFERROR(G21-F21,"") | K21: =IF(I21="","",IF(I21<30,"⚠ Expiring",IF(I21<90,"Watch","OK")))
I22: =IFERROR(H22-TODAY(),"") | J22: =IFERROR(G22-F22,"") | K22: =IF(I22="","",IF(I22<30,"⚠ Expiring",IF(I22<90,"Watch","OK")))
I23: =IFERROR(H23-TODAY(),"") | J23: =IFERROR(G23-F23,"") | K23: =IF(I23="","",IF(I23<30,"⚠ Expiring",IF(I23<90,"Watch","OK")))
I24: =IFERROR(H24-TODAY(),"") | J24: =IFERROR(G24-F24,"") | K24: =IF(I24="","",IF(I24<30,"⚠ Expiring",IF(I24<90,"Watch","OK")))
B25: RSU + ESPP vesting calendar
B26: Per-grant rows × per-vest-date columns. Vested becomes employer-stock concentration; unvested is future taxable income.
B29: Ticker | C29: Type | D29: Grant Date | E29: Grant $ | F29: Vest Schedule | G29: Next Vest | H29: # Vested | I29: Vested $ | J29: Unvested $ | K29: Lockup End | L29: Sell Plan
B30: TECH | C30: RSU | D30: 44972 | E30: 52000 | F30: 4-yr cliff+vest | G30: 45703 | H30: 60 | I30: 6000 | J30: 39000 | L30: Sell on vest
B31: TECH | C31: ESPP | D31: 45139 | E31: 5000 | F31: 6-mo offering | G31: 45689 | H31: 25 | I31: 2500 | J31: 0 | K31: N/A | L31: Sell at end of offering
B46: 🎯 Default policy: sell on vest RSU compensation already gives you the employer-stock exposure. Holding past vest is voluntary additional concentration on top of compensation. The "wait for LTCG" temptation usually costs more than the LTCG tax differential (1 year of volatility risk on a single-name concentration). Concentration Risk Alerter (page 5) walks the math.
A51: Lime Premium Studios · Investment Portfolio Tracker Pro v1.0 · Privacy-first. No Plaid. No app.

Sheet 📊 Performance & Returns
A1: Lime Premium Studios | D1: Investment Portfolio Tracker — Pro | J1: 📊 Performance & Returns
A2: ="1yr TWR"&CHAR(10)&(TEXT(IFERROR(C12,0),"+0.0%;-0.0%")) | C2: ="3yr CAGR"&CHAR(10)&(TEXT(IFERROR(D12,0),"+0.0%;-0.0%")) | E2: ="5yr CAGR"&CHAR(10)&(TEXT(IFERROR(E12,0),"+0.0%;-0.0%")) | G2: ="INCEPTION"&CHAR(10)&(TEXT(IFERROR(G12,0),"+0.0%;-0.0%")) | I2: BENCHMARK S&P 500 | K2: ="vs BENCH"&CHAR(10)&(TEXT(IFERROR(C12-C13,0),"+0.0%;-0.0%"))
A3: ✦ Why a Spreadsheet, Not an App? Sharesight $96/yr. Stock Rover $300/yr. Kubera $200/yr. We charge $17 once. No broker linking — your credentials stay at your broker.
A4: TWR vs benchmark + MWR table. CAGR over 1yr / 3yr / 5yr / 10yr / since-inception. Custom benchmark configurable.
B6: Multi-horizon returns
B7: TWR = Time-Weighted Return (compares vs index, ignores contribution timing). MWR = Money-Weighted Return (IRR, includes contributions).
B10: Metric | C10: 1 Yr | D10: 3 Yr CAGR | E10: 5 Yr CAGR | F10: 10 Yr CAGR | G10: YTD | H10: Inception | I10: MWR (IRR)
B11: Your Portfolio (TWR) | C11: 0.124 | D11: 0.085 | E11: 0.092 | F11: 0.095 | G11: 0.086 | H11: 0.108 | I11: 0.105
B12: S&P 500 (benchmark) | C12: 0.108 | D12: 0.078 | E12: 0.105 | F12: 0.122 | G12: 0.08 | H12: 0.098
B13: MSCI World | C13: 0.094 | D13: 0.072 | E13: 0.088 | F13: 0.095 | G13: 0.071 | H13: 0.082
B14: 60/40 Stocks/Bonds | C14: 0.082 | D14: 0.058 | E14: 0.065 | F14: 0.072 | G14: 0.061 | H14: 0.071
B15: Outperformance vs S&P 500 | C15: =C11-C12 | D15: =D11-D12 | E15: =E11-E12 | F15: =F11-F12 | G15: =G11-G12 | H15: =H11-H12
B18: 📐 TWR vs MWR — they answer different questions TWR strips out contribution timing — best for comparing investment SKILL against an index. MWR (IRR) includes contributions — best for "how did MY money actually grow?" If TWR > MWR, you contributed during dips. If TWR < MWR, you contributed during rallies. Both numbers are honest.
A24: Lime Premium Studios · Investment Portfolio Tracker Pro v1.0 · Privacy-first. No Plaid. No app.

Sheet 📐 Risk Metrics
A1: Lime Premium Studios | D1: Investment Portfolio Tracker — Pro | J1: 📐 Risk Metrics
A2: ="SHARPE"&CHAR(10)&(TEXT(IFERROR(C9,0),"0.00")) | C2: ="BETA"&CHAR(10)&(TEXT(IFERROR(C12,0),"0.00")) | E2: ="MAX DRAWDOWN"&CHAR(10)&(TEXT(IFERROR(C15,0),"0.0%")) | G2: ="ANN VOLATILITY"&CHAR(10)&(TEXT(IFERROR(C18,0),"0.0%")) | I2: BENCHMARK S&P 500 | K2: RISK-FREE 4.5% (10yr UST)
A3: ✦ Why a Spreadsheet, Not an App? Sharesight $96/yr. Stock Rover $300/yr. Kubera $200/yr. We charge $17 once. No broker linking — your credentials stay at your broker.
A4: Sharpe / Beta / Max Drawdown / Volatility — the numbers Sharesight charges $96/year for. Computed from your monthly returns.
B6: Four core risk metrics
B7: Each card shows the metric + sector benchmark + plain-English interpretation.
B11: Sharpe Ratio | G11: Beta
B12: 1.18 | G12: 1.05
B13: Benchmark: S&P 500 ~0.85 | G13: Benchmark: 1.0 = matches market
B14: >1.0 = strong risk-adjusted return. <0.5 = under-compensated for volatility. | G14: Your portfolio moves ~5% more than S&P 500 on big swings. Elevated tech weighting.
B17: Max Drawdown | G17: Annualized Vol
B18: -0.184 | G18: 0.145
B19: Benchmark: S&P 2020: -34%; 2022: -25% | G19: Benchmark: S&P 500 long-run ~0.16
B20: Largest peak-to-trough loss in the period. -18.4% would scare some investors out. | G20: Std dev of monthly returns × √12. Slightly below market — diversification working.
B23: 📐 Real metrics, simple math Sharpe = (portfolio return - risk-free rate) / std dev of returns. Beta = covariance vs benchmark / variance of benchmark. Max Drawdown = (trough - peak) / peak from your monthly NAV log. Volatility = stdev of monthly returns × sqrt(12). Same formulas Sharesight + Stock Rover use — we just show them in cells you can verify.
A29: Lime Premium Studios · Investment Portfolio Tracker Pro v1.0 · Privacy-first. No Plaid. No app.

Sheet 🧾 Tax Lot Tracker
A1: Lime Premium Studios | D1: Investment Portfolio Tracker — Pro | J1: 🧾 Tax Lot Tracker
A2: ="LOTS"&CHAR(10)&(COUNTA(B9:B40)) | C2: ="LONG-TERM"&CHAR(10)&(COUNTIF(K9:K40,"Long-term")) | E2: ="SHORT-TERM"&CHAR(10)&(COUNTIF(K9:K40,"Short-term")) | G2: ="UNREALIZED"&CHAR(10)&(TEXT(SUM(J9:J40),"+$#,##0;-$#,##0")) | I2: ="REGION"&CHAR(10)&(IFERROR(L8,"US")) | K2: METHOD FIFO/LIFO/Spec
A3: ✦ Why a Spreadsheet, Not an App? Sharesight $96/yr. Stock Rover $300/yr. Kubera $200/yr. We charge $17 once. No broker linking — your credentials stay at your broker.
A4: Per-lot cost basis. Short-term vs long-term color-coded. Region toggle (US/UK/EU/AU/CA — AI Edition only).
B6: Per-lot cost basis log
B7: Required for accurate cost basis on partial sells. FIFO = sell oldest lots first (default for most brokers); Spec = pick which lot.
B10: Ticker | C10: Acquired | D10: Shares | E10: Cost/sh | F10: Cost Basis | G10: Curr Price | H10: Curr Value | I10: Holding | J10: Unrealized | K10: G/L Type | L10: Lot ID
B11: VTI | C11: 45092 | D11: 150 | E11: 185.4 | F11: =IFERROR(D11*E11,"") | G11: 245 | H11: =IFERROR(D11*G11,"") | I11: =IFERROR(TODAY()-C11,"") | J11: =IFERROR(H11-F11,"") | K11: =IF(I11="","",IF(I11>365,"Long-term","Short-term"))
B12: VTI | C12: 45313 | D12: 100 | E12: 210 | F12: =IFERROR(D12*E12,"") | G12: 245 | H12: =IFERROR(D12*G12,"") | I12: =IFERROR(TODAY()-C12,"") | J12: =IFERROR(H12-F12,"") | K12: =IF(I12="","",IF(I12>365,"Long-term","Short-term"))
B13: VTI | C13: 45519 | D13: 100 | E13: 232 | F13: =IFERROR(D13*E13,"") | G13: 245 | H13: =IFERROR(D13*G13,"") | I13: =IFERROR(TODAY()-C13,"") | J13: =IFERROR(H13-F13,"") | K13: =IF(I13="","",IF(I13>365,"Long-term","Short-term"))
B14: AAPL | C14: 44870 | D14: 80 | E14: 128 | F14: =IFERROR(D14*E14,"") | G14: 182 | H14: =IFERROR(D14*G14,"") | I14: =IFERROR(TODAY()-C14,"") | J14: =IFERROR(H14-F14,"") | K14: =IF(I14="","",IF(I14>365,"Long-term","Short-term"))
B15: GOOGL | C15: 44995 | D15: 70 | E15: 105.5 | F15: =IFERROR(D15*E15,"") | G15: 148 | H15: =IFERROR(D15*G15,"") | I15: =IFERROR(TODAY()-C15,"") | J15: =IFERROR(H15-F15,"") | K15: =IF(I15="","",IF(I15>365,"Long-term","Short-term"))
F16: =IFERROR(D16*E16,"") | H16: =IFERROR(D16*G16,"") | I16: =IFERROR(TODAY()-C16,"") | J16: =IFERROR(H16-F16,"") | K16: =IF(I16="","",IF(I16>365,"Long-term","Short-term"))
F17: =IFERROR(D17*E17,"") | H17: =IFERROR(D17*G17,"") | I17: =IFERROR(TODAY()-C17,"") | J17: =IFERROR(H17-F17,"") | K17: =IF(I17="","",IF(I17>365,"Long-term","Short-term"))
F18: =IFERROR(D18*E18,"") | H18: =IFERROR(D18*G18,"") | I18: =IFERROR(TODAY()-C18,"") | J18: =IFERROR(H18-F18,"") | K18: =IF(I18="","",IF(I18>365,"Long-term","Short-term"))
F19: =IFERROR(D19*E19,"") | H19: =IFERROR(D19*G19,"") | I19: =IFERROR(TODAY()-C19,"") | J19: =IFERROR(H19-F19,"") | K19: =IF(I19="","",IF(I19>365,"Long-term","Short-term"))
F20: =IFERROR(D20*E20,"") | H20: =IFERROR(D20*G20,"") | I20: =IFERROR(TODAY()-C20,"") | J20: =IFERROR(H20-F20,"") | K20: =IF(I20="","",IF(I20>365,"Long-term","Short-term"))
F21: =IFERROR(D21*E21,"") | H21: =IFERROR(D21*G21,"") | I21: =IFERROR(TODAY()-C21,"") | J21: =IFERROR(H21-F21,"") | K21: =IF(I21="","",IF(I21>365,"Long-term","Short-term"))
F22: =IFERROR(D22*E22,"") | H22: =IFERROR(D22*G22,"") | I22: =IFERROR(TODAY()-C22,"") | J22: =IFERROR(H22-F22,"") | K22: =IF(I22="","",IF(I22>365,"Long-term","Short-term"))
F23: =IFERROR(D23*E23,"") | H23: =IFERROR(D23*G23,"") | I23: =IFERROR(TODAY()-C23,"") | J23: =IFERROR(H23-F23,"") | K23: =IF(I23="","",IF(I23>365,"Long-term","Short-term"))
F24: =IFERROR(D24*E24,"") | H24: =IFERROR(D24*G24,"") | I24: =IFERROR(TODAY()-C24,"") | J24: =IFERROR(H24-F24,"") | K24: =IF(I24="","",IF(I24>365,"Long-term","Short-term"))
F25: =IFERROR(D25*E25,"") | H25: =IFERROR(D25*G25,"") | I25: =IFERROR(TODAY()-C25,"") | J25: =IFERROR(H25-F25,"") | K25: =IF(I25="","",IF(I25>365,"Long-term","Short-term"))
F26: =IFERROR(D26*E26,"") | H26: =IFERROR(D26*G26,"") | I26: =IFERROR(TODAY()-C26,"") | J26: =IFERROR(H26-F26,"") | K26: =IF(I26="","",IF(I26>365,"Long-term","Short-term"))
F27: =IFERROR(D27*E27,"") | H27: =IFERROR(D27*G27,"") | I27: =IFERROR(TODAY()-C27,"") | J27: =IFERROR(H27-F27,"") | K27: =IF(I27="","",IF(I27>365,"Long-term","Short-term"))
... F42: =IFERROR(D42*E42,"") | H42: =IFERROR(D42*G42,"") | I42: =IFERROR(TODAY()-C42,"") | J42: =IFERROR(H42-F42,"") | K42: =IF(I42="","",IF(I42>365,"Long-term","Short-term"))
B45: 🧾 Specific-lot selection saves taxes on partial sells Default broker behavior is FIFO (sell oldest lots first). But "specific lot" lets you pick — e.g., when raising cash from VTI, sell the HIGHEST-cost-basis lot to minimize realized gain. Most brokers allow this if you specify at the time of sale; document the lot ID in column L when you do.
A51: Lime Premium Studios · Investment Portfolio Tracker Pro v1.0 · Privacy-first. No Plaid. No app.

Sheet 📉 Tax-Loss Harvesting
A1: Lime Premium Studios | D1: Investment Portfolio Tracker — Pro | J1: 📉 Tax-Loss Harvesting
A2: ="CANDIDATES"&CHAR(10)&(COUNTIF(F9:F22,"<0")) | C2: ="LOSS $"&CHAR(10)&(TEXT(SUMIF(F9:F22,"<0"),"$#,##0")) | E2: ="TAX SAVINGS"&CHAR(10)&(TEXT(IFERROR(-SUMIF(F9:F22,"<0")*0.24,0),"$#,##0")) | G2: ="WASH BLOCKED"&CHAR(10)&(COUNTIF(I9:I22,"🔴*")) | I2: STCG OFFSET $3K/yr cap | K2: ="REGION"&CHAR(10)&('🧾 Tax Lot Tracker'!L8)
A3: ✦ Why a Spreadsheet, Not an App? Sharesight $96/yr. Stock Rover $300/yr. Kubera $200/yr. We charge $17 once. No broker linking — your credentials stay at your broker.
A4: Eligible positions with unrealized losses. Wash-sale window (30-day pre + post) check. Suggested replacement security per position.
B6: Tax-loss harvesting candidates
B7: Positions with unrealized losses. Wash-sale check looks at any same-or-substantially-identical buy in last 30 days (or planned next 30) across ALL accounts including spouse + IRA.
B10: Ticker | C10: Account | D10: Shares | E10: Cost Basis | F10: Curr Value | G10: Loss $ | H10: Loss % | I10: Wash Window | J10: Replacement | K10: Tax Save | L10: Priority
B11: BND | C11: Brokerage Taxable | D11: 250 | E11: 18550 | F11: 18100 | G11: =IFERROR(F11-E11,"") | H11: =IFERROR(G11/E11,"") | I11: ✓ Clear | J11: AGG or SCHZ | K11: =IFERROR(MAX(0,-G11)*0.24,0) | L11: Low — small $
B12: VXUS | C12: Brokerage Taxable | D12: 180 | E12: 10224 | F12: 10764 | G12: =IFERROR(F12-E12,"") | H12: =IFERROR(G12/E12,"") | I12: 🔴 BLOCKED 22 days | J12: IXUS (still wash-risk) | K12: =IFERROR(MAX(0,-G12)*0.24,0) | L12: 🔴 Wash via IRA
